ERROR:root:Exception
Traceback (most recent call last):
  File "/home/pavel/ISP/EXAM/main.py", line 14, in wrapper
    return func()
  File "/home/pavel/ISP/EXAM/main.py", line 33, in test_f
    raise RuntimeError
RuntimeError
